Workbook

Sheet Dashboard Report
A1: 📊 DASHBOARD BÁO CÁO TNI — 07/06/2026 23:21
A2: Kỳ báo cáo: 3 Ngày (D-2/D-1/HN) | 7 Ngày liền kề | 1 Tháng: 21/05/2026 → 07/06/2026
A3: → Dùng sheet 'Dashboard Raw' + Data → Add a slicer để lọc
A5: 🔍 1. THỐNG KÊ TÌM KIẾM — TỪNG NGƯỜI
A6: STT | B6: Họ tên | C6: Đội | D6: Vai trò | E6: 3Ngày (D-2/D-1/HN) | F6: D-2 | G6: D-1 | H6: Hôm nay | I6: 7 Ngày | J6: 1 Tháng
A7: 1 | B7: Aung Lwin Phyo | C7: MYT_TNI_TEAM01_Dawei | D7: Nhân viên | E7: 0/0/0 | F7: 0 | G7: 0 | H7: 0 | I7: 0 | J7: 0
A8: 2 | B8: Bhone Htet Aung | C8: MYT_TNI_TEAM01_Dawei | D8: Nhân viên | E8: 0/0/0 | F8: 0 | G8: 0 | H8: 0 | I8: 0 | J8: 0
A9: 3 | B9: Bone Myat Naing | C9: MYT_TNI_TEAM01_Dawei | D9: Nhân viên | E9: 0/0/0 | F9: 0 | G9: 0 | H9: 0 | I9: 0 | J9: 0
A10: 4 | B10: Win Htet Aung | C10: MYT_TNI_TEAM01_Dawei | D10: Nhân viên | E10: 0/0/0 | F10: 0 | G10: 0 | H10: 0 | I10: 0 | J10: 0
A11: 5 | B11: Thar Htoo Aung | C11: MYT_TNI_TEAM01_Dawei | D11: Nhân viên | E11: 0/0/0 | F11: 0 | G11: 0 | H11: 0 | I11: 0 | J11: 0
A12: 6 | B12: Maung Maung | C12: MYT_TNI_TEAM02_Myeik | D12: Nhân viên | E12: 0/0/0 | F12: 0 | G12: 0 | H12: 0 | I12: 0 | J12: 0
A13: 7 | B13: Min Paing Oo | C13: MYT_TNI_TEAM02_Myeik | D13: Nhân viên | E13: 0/0/0 | F13: 0 | G13: 0 | H13: 0 | I13: 0 | J13: 0
A14: 8 | B14: Zin Min Shein | C14: MYT_TNI_TEAM02_Myeik | D14: Nhân viên | E14: 0/0/0 | F14: 0 | G14: 0 | H14: 0 | I14: 0 | J14: 0
A15: 9 | B15: Ye Lin | C15: MYT_TNI_TEAM02_Myeik | D15: Nhân viên | E15: 0/0/0 | F15: 0 | G15: 0 | H15: 0 | I15: 0 | J15: 0
A16: 10 | B16: Wanna Oo | C16: MYT_TNI_TEAM02_Myeik | D16: Nhân viên | E16: 0/0/0 | F16: 0 | G16: 0 | H16: 0 | I16: 0 | J16: 0
A17: 11 | B17: Myint Ko Ko Aung | C17: MYT_TNI_TEAM03_Bokpyin | D17: Nhân viên | E17: 0/0/0 | F17: 0 | G17: 0 | H17: 0 | I17: 0 | J17: 0
A18: 12 | B18: - | C18: MYT_TNI_TEAM04_Kawthoung | D18: Nhân viên | E18: 0/0/0 | F18: 0 | G18: 0 | H18: 0 | I18: 0 | J18: 0
... A25: 19 | B25: Naing Myo Htun | C25: MYT_TNI_TEAM04_Kawthoung | D25: Team Leader | E25: 0/0/0 | F25: 0 | G25: 0 | H25: 0 | I25: 0 | J25: 0
A26: TỔNG | F26: =SUM(F7:F25) -> 0 | G26: =SUM(G7:G25) -> 0 | H26: =SUM(H7:H25) -> 0 | I26: =SUM(I7:I25) -> 0 | J26: =SUM(J7:J25) -> 0
A28: 🏷️ 2. THỐNG KÊ TÌM KIẾM — THEO ĐỘI
A29: STT | B29: Tên Đội | C29: Số TV | D29: 3Ngày (D-2/D-1/HN) | E29: D-2 | F29: D-1 | G29: Hôm nay | H29: 7 Ngày | I29: 1 Tháng
A30: 1 | B30: MYT_TNI_TEAM01_Dawei | C30: 6 | D30: 0/0/0 | E30: 0 | F30: 0 | G30: 0 | H30: 0 | I30: 0
A31: 2 | B31: MYT_TNI_TEAM02_Myeik | C31: 6 | D31: 0/0/0 | E31: 0 | F31: 0 | G31: 0 | H31: 0 | I31: 0
A32: 3 | B32: MYT_TNI_TEAM03_Bokpyin | C32: 3 | D32: 0/0/0 | E32: 0 | F32: 0 | G32: 0 | H32: 0 | I32: 0
A33: 4 | B33: MYT_TNI_TEAM04_Kawthoung | C33: 4 | D33: 0/0/0 | E33: 0 | F33: 0 | G33: 0 | H33: 0 | I33: 0
A34: TỔNG | C34: =SUM(C30:C33) -> 19 | E34: =SUM(E30:E33) -> 0 | F34: =SUM(F30:F33) -> 0 | G34: =SUM(G30:G33) -> 0 | H34: =SUM(H30:H33) -> 0 | I34: =SUM(I30:I33) -> 0
A36: 📦 3. THỐNG KÊ ASSET — THEO ĐỘI & LOẠI
A37: STT | B37: Đội | C37: Loại Asset | D37: 3Ngày (D-2/D-1/HN) | E37: D-2 | F37: D-1 | G37: Hôm nay | H37: 7 Ngày | I37: 1 Tháng | J37: Tổng | K37: Xong | L37: % Done
A38: 1 | B38: Management | C38: Move | D38: 0/1/0 | E38: 0 | F38: 1 | G38: 0 | H38: 1 | I38: 1 | J38: 1 | K38: 0 | L38: 0
A39: 2 | B39: Management | C39: Order | D39: 0/0/0 | E39: 0 | F39: 0 | G39: 0 | H39: 1 | I39: 1 | J39: 1 | K39: 0 | L39: 0
A40: ▶ TỔNG TẤT CẢ TEAM
A41: → | B41: ALL | C41: Move | D41: 0/1/0 | E41: 0 | F41: 1 | G41: 0 | H41: 1 | I41: 1 | J41: 1 | K41: 0 | L41: 0
A42: → | B42: ALL | C42: Order | D42: 0/0/0 | E42: 0 | F42: 0 | G42: 0 | H42: 1 | I42: 1 | J42: 1 | K42: 0 | L42: 0
A44: 🔧 4. TECHNICAL DEP — TASK PROGRESS (Rows 75-87)
A45: STT | B45: Phòng ban | C45: Task Tổng | D45: Task Xong | E45: Còn lại | F45: % Done | G45: 3Day (D-2/D-1/HN) | H45: 7 Day | I45: 1 Month | J45: Nội dung
A46: 1 | B46: Admin | C46: 3 | D46: 0 | E46: 3 | F46: 0 | G46: 0/0/0 | H46: 0 | I46: 0
A47: 2 | B47: Finance | C47: 29 | D47: 7 | E47: 22 | F47: 0.24 | G47: 0/0/0 | H47: 0 | I47: 0
A48: 3 | B48: M&E | C48: 132 | D48: 11 | E48: 121 | F48: 0.08 | G48: 0/0/0 | H48: 0 | I48: 0
A49: 4 | B49: PM | C49: 116 | D49: 25 | E49: 91 | F49: 0.22 | G49: 0/0/0 | H49: 0 | I49: 0
A50: 5 | B50: Transmission | C50: 3 | D50: 1 | E50: 2 | F50: 0.33 | G50: 0/0/0 | H50: 0 | I50: 0
...

Sheet Asset Stats Log
A1: Date | B1: Time | C1: Team | D1: Team Short | E1: Action | F1: Total | G1: Done | H1: Today | I1: Yesterday | J1: 2 Days Ago | K1: Week(7d) | L1: Month(15d) | M1: Done Today | N1: Done Yesterday | O1: Done 2Days | P1: Done Week | Q1: Done Month
A2: 46301 | B2: 0.81666667 | C2: MYT_TNI_TEAM01_Dawei | D2: Team1(Dawei) | E2: Order | F2: 0 | G2: 0 | H2: 0 | I2: 0 | J2: 0 | K2: 0 | L2: 0 | M2: 0 | N2: 0 | O2: 0 | P2: 0 | Q2: 0
A3: 46301 | B3: 0.81666667 | C3: MYT_TNI_TEAM01_Dawei | D3: Team1(Dawei) | E3: Revoke | F3: 0 | G3: 0 | H3: 0 | I3: 0 | J3: 0 | K3: 0 | L3: 0 | M3: 0 | N3: 0 | O3: 0 | P3: 0 | Q3: 0
A4: 46301 | B4: 0.81666667 | C4: MYT_TNI_TEAM01_Dawei | D4: Team1(Dawei) | E4: Export | F4: 0 | G4: 0 | H4: 0 | I4: 0 | J4: 0 | K4: 0 | L4: 0 | M4: 0 | N4: 0 | O4: 0 | P4: 0 | Q4: 0
A5: 46301 | B5: 0.81666667 | C5: MYT_TNI_TEAM01_Dawei | D5: Team1(Dawei) | E5: Move | F5: 0 | G5: 0 | H5: 0 | I5: 0 | J5: 0 | K5: 0 | L5: 0 | M5: 0 | N5: 0 | O5: 0 | P5: 0 | Q5: 0
A6: 46301 | B6: 0.81666667 | C6: MYT_TNI_TEAM01_Dawei | D6: Team1(Dawei) | E6: Asset Sent | F6: 0 | G6: 0 | H6: 0 | I6: 0 | J6: 0 | K6: 0 | L6: 0 | M6: 0 | N6: 0 | O6: 0 | P6: 0 | Q6: 0
A7: 46301 | B7: 0.81666667 | C7: MYT_TNI_TEAM01_Dawei | D7: Team1(Dawei) | E7: Destroys | F7: 0 | G7: 0 | H7: 0 | I7: 0 | J7: 0 | K7: 0 | L7: 0 | M7: 0 | N7: 0 | O7: 0 | P7: 0 | Q7: 0
A8: 46301 | B8: 0.81666667 | C8: MYT_TNI_TEAM01_Dawei | D8: Team1(Dawei) | E8: Loss fuel | F8: 0 | G8: 0 | H8: 0 | I8: 0 | J8: 0 | K8: 0 | L8: 0 | M8: 0 | N8: 0 | O8: 0 | P8: 0 | Q8: 0
A9: 46301 | B9: 0.81666667 | C9: MYT_TNI_TEAM02_Myeik | D9: Team2(Myeik) | E9: Order | F9: 1 | G9: 1 | H9: 0 | I9: 0 | J9: 0 | K9: 1 | L9: 1 | M9: 0 | N9: 0 | O9: 0 | P9: 1 | Q9: 1
A10: 46301 | B10: 0.81666667 | C10: MYT_TNI_TEAM02_Myeik | D10: Team2(Myeik) | E10: Revoke | F10: 0 | G10: 0 | H10: 0 | I10: 0 | J10: 0 | K10: 0 | L10: 0 | M10: 0 | N10: 0 | O10: 0 | P10: 0 | Q10: 0
A11: 46301 | B11: 0.81666667 | C11: MYT_TNI_TEAM02_Myeik | D11: Team2(Myeik) | E11: Export | F11: 0 | G11: 0 | H11: 0 | I11: 0 | J11: 0 | K11: 0 | L11: 0 | M11: 0 | N11: 0 | O11: 0 | P11: 0 | Q11: 0
A12: 46301 | B12: 0.81666667 | C12: MYT_TNI_TEAM02_Myeik | D12: Team2(Myeik) | E12: Move | F12: 0 | G12: 0 | H12: 0 | I12: 0 | J12: 0 | K12: 0 | L12: 0 | M12: 0 | N12: 0 | O12: 0 | P12: 0 | Q12: 0
A13: 46301 | B13: 0.81666667 | C13: MYT_TNI_TEAM02_Myeik | D13: Team2(Myeik) | E13: Asset Sent | F13: 0 | G13: 0 | H13: 0 | I13: 0 | J13: 0 | K13: 0 | L13: 0 | M13: 0 | N13: 0 | O13: 0 | P13: 0 | Q13: 0
... A316: 46362 | B316: 0.73472222 | C316: GRAND TOTAL | D316: Total | E316: Loss fuel | F316: 0 | G316: 0 | H316: 0 | I316: 0 | J316: 0 | K316: 0 | L316: 0 | M316: 0 | N316: 0 | O316: 0 | P316: 0 | Q316: 0
A317: 13/06/2026 | B317: 0.73541667 | C317: MYT_TNI_TEAM01_Dawei | D317: Team1(Dawei) | E317: Order | F317: 0 | G317: 0 | H317: 0 | I317: 0 | J317: 0 | K317: 0 | L317: 0 | M317: 0 | N317: 0 | O317: 0 | P317: 0 | Q317: 0
A318: 13/06/2026 | B318: 0.73541667 | C318: MYT_TNI_TEAM01_Dawei | D318: Team1(Dawei) | E318: Revoke | F318: 0 | G318: 0 | H318: 0 | I318: 0 | J318: 0 | K318: 0 | L318: 0 | M318: 0 | N318: 0 | O318: 0 | P318: 0 | Q318: 0
A319: 13/06/2026 | B319: 0.73541667 | C319: MYT_TNI_TEAM01_Dawei | D319: Team1(Dawei) | E319: Export | F319: 0 | G319: 0 | H319: 0 | I319: 0 | J319: 0 | K319: 0 | L319: 0 | M319: 0 | N319: 0 | O319: 0 | P319: 0 | Q319: 0
A320: 13/06/2026 | B320: 0.73541667 | C320: MYT_TNI_TEAM01_Dawei | D320: Team1(Dawei) | E320: Move | F320: 0 | G320: 0 | H320: 0 | I320: 0 | J320: 0 | K320: 0 | L320: 0 | M320: 0 | N320: 0 | O320: 0 | P320: 0 | Q320: 0
A321: 13/06/2026 | B321: 0.73541667 | C321: MYT_TNI_TEAM01_Dawei | D321: Team1(Dawei) | E321: Asset Sent | F321: 0 | G321: 0 | H321: 0 | I321: 0 | J321: 0 | K321: 0 | L321: 0 | M321: 0 | N321: 0 | O321: 0 | P321: 0 | Q321: 0
A322: 13/06/2026 | B322: 0.73541667 | C322: MYT_TNI_TEAM01_Dawei | D322: Team1(Dawei) | E322: Destroys | F322: 0 | G322: 0 | H322: 0 | I322: 0 | J322: 0 | K322: 0 | L322: 0 | M322: 0 | N322: 0 | O322: 0 | P322: 0 | Q322: 0
A323: 13/06/2026 | B323: 0.73541667 | C323: MYT_TNI_TEAM01_Dawei | D323: Team1(Dawei) | E323: Loss fuel | F323: 0 | G323: 0 | H323: 0 | I323: 0 | J323: 0 | K323: 0 | L323: 0 | M323: 0 | N323: 0 | O323: 0 | P323: 0 | Q323: 0
A324: 13/06/2026 | B324: 0.73541667 | C324: MYT_TNI_TEAM02_Myeik | D324: Team2(Myeik) | E324: Order | F324: 1 | G324: 1 | H324: 0 | I324: 0 | J324: 0 | K324: 1 | L324: 1 | M324: 0 | N324: 0 | O324: 0 | P324: 1 | Q324: 1
A325: 13/06/2026 | B325: 0.73541667 | C325: MYT_TNI_TEAM02_Myeik | D325: Team2(Myeik) | E325: Revoke | F325: 0 | G325: 0 | H325: 0 | I325: 0 | J325: 0 | K325: 0 | L325: 0 | M325: 0 | N325: 0 | O325: 0 | P325: 0 | Q325: 0
A326: 13/06/2026 | B326: 0.73541667 | C326: MYT_TNI_TEAM02_Myeik | D326: Team2(Myeik) | E326: Export | F326: 0 | G326: 0 | H326: 0 | I326: 0 | J326: 0 | K326: 0 | L326: 0 | M326: 0 | N326: 0 | O326: 0 | P326: 0 | Q326: 0
A327: 13/06/2026 | B327: 0.73541667 | C327: MYT_TNI_TEAM02_Myeik | D327: Team2(Myeik) | E327: Move | F327: 0 | G327: 0 | H327: 0 | I327: 0 | J327: 0 | K327: 0 | L327: 0 | M327: 0 | N327: 0 | O327: 0 | P327: 0 | Q327: 0
A328: 13/06/2026 | B328: 0.73541667 | C328: MYT_TNI_TEAM02_Myeik | D328: Team2(Myeik) | E328: Asset Sent | F328: 0 | G328: 0 | H328: 0 | I328: 0 | J328: 0 | K328: 0 | L328: 0 | M328: 0 | N328: 0 | O328: 0 | P328: 0 | Q328: 0
... A731: 23/06/2026 | B731: 0.73541667 | C731: GRAND TOTAL | D731: Total | E731: Inventory water coolant | F731: 0 | G731: 0 | H731: 0 | I731: 0 | J731: 0 | K731: 0 | L731: 0 | M731: 0 | N731: 0 | O731: 0 | P731: 0 | Q731: 0
A732: 46197 | B732: 0.73472222 | C732: MYT_TNI_TEAM01_Dawei | D732: Team1(Dawei) | E732: Order | F732: 3 | G732: 2 | H732: 0 | I732: 0 | J732: 1 | K732: 2 | L732: 3 | M732: 0 | N732: 0 | O732: 1 | P732: 1 | Q732: 2
A733: 46197 | B733: 0.73472222 | C733: MYT_TNI_TEAM01_Dawei | D733: Team1(Dawei) | E733: Revoke | F733: 0 | G733: 0 | H733: 0 | I733: 0 | J733: 0 | K733: 0 | L733: 0 | M733: 0 | N733: 0 | O733: 0 | P733: 0 | Q733: 0
A734: 46197 | B734: 0.73472222 | C734: MYT_TNI_TEAM01_Dawei | D734: Team1(Dawei) | E734: Export | F734: 0 | G734: 0 | H734: 0 | I734: 0 | J734: 0 | K734: 0 | L734: 0 | M734: 0 | N734: 0 | O734: 0 | P734: 0 | Q734: 0
A735: 46197 | B735: 0.73472222 | C735: MYT_TNI_TEAM01_Dawei | D735: Team1(Dawei) | E735: Move | F735: 0 | G735: 0 | H735: 0 | I735: 0 | J735: 0 | K735: 0 | L735: 0 | M735: 0 | N735: 0 | O735: 0 | P735: 0 | Q735: 0
A736: 46197 | B736: 0.73472222 | C736: MYT_TNI_TEAM01_Dawei | D736: Team1(Dawei) | E736: Asset Sent | F736: 0 | G736: 0 | H736: 0 | I736: 0 | J736: 0 | K736: 0 | L736: 0 | M736: 0 | N736: 0 | O736: 0 | P736: 0 | Q736: 0
A737: 46197 | B737: 0.73472222 | C737: MYT_TNI_TEAM01_Dawei | D737: Team1(Dawei) | E737: Destroys | F737: 0 | G737: 0 | H737: 0 | I737: 0 | J737: 0 | K737: 0 | L737: 0 | M737: 0 | N737: 0 | O737: 0 | P737: 0 | Q737: 0
A738: 46197 | B738: 0.73472222 | C738: MYT_TNI_TEAM01_Dawei | D738: Team1(Dawei) | E738: Loss fuel | F738: 0 | G738: 0 | H738: 0 | I738: 0 | J738: 0 | K738: 0 | L738: 0 | M738: 0 | N738: 0 | O738: 0 | P738: 0 | Q738: 0
A739: 46197 | B739: 0.73472222 | C739: MYT_TNI_TEAM01_Dawei | D739: Team1(Dawei) | E739: Inventory oil | F739: 0 | G739: 0 | H739: 0 | I739: 0 | J739: 0 | K739: 0 | L739: 0 | M739: 0 | N739: 0 | O739: 0 | P739: 0 | Q739: 0
A740: 46197 | B740: 0.73472222 | C740: MYT_TNI_TEAM01_Dawei | D740: Team1(Dawei) | E740: Inventory water coolant | F740: 0 | G740: 0 | H740: 0 | I740: 0 | J740: 0 | K740: 0 | L740: 0 | M740: 0 | N740: 0 | O740: 0 | P740: 0 | Q740: 0
A741: 46197 | B741: 0.73472222 | C741: MYT_TNI_TEAM02_Myeik | D741: Team2(Myeik) | E741: Order | F741: 1 | G741: 1 | H741: 0 | I741: 0 | J741: 0 | K741: 1 | L741: 1 | M741: 0 | N741: 0 | O741: 0 | P741: 1 | Q741: 1
A742: 46197 | B742: 0.73472222 | C742: MYT_TNI_TEAM02_Myeik | D742: Team2(Myeik) | E742: Revoke | F742: 0 | G742: 0 | H742: 0 | I742: 0 | J742: 0 | K742: 0 | L742: 0 | M742: 0 | N742: 0 | O742: 0 | P742: 0 | Q742: 0
A743: 46197 | B743: 0.73472222 | C743: MYT_TNI_TEAM02_Myeik | D743: Team2(Myeik) | E743: Export | F743: 0 | G743: 0 | H743: 0 | I743: 0 | J743: 0 | K743: 0 | L743: 0 | M743: 0 | N743: 0 | O743: 0 | P743: 0 | Q743: 0
... A1676: 46205 | B1676: 0.73541667 | C1676: GRAND TOTAL | D1676: Total | E1676: Inventory water coolant | F1676: 0 | G1676: 0 | H1676: 0 | I1676: 0 | J1676: 0 | K1676: 0 | L1676: 0 | M1676: 0 | N1676: 0 | O1676: 0 | P1676: 0 | Q1676: 0

Sheet Dashboard Raw
A1: Ngày | B1: Loại | C1: Tên / Phòng ban | D1: Đội | E1: Vai trò | F1: Search D-2 | G1: Search D-1 | H1: Search HN | I1: Search 7Ngày | J1: Search 1Tháng | K1: Search 3Ngày | L1: Asset Loại | M1: Asset D-2 | N1: Asset D-1 | O1: Asset HN | P1: Asset 7Ngày | Q1: Asset 1Tháng | R1: Asset Tổng | S1: Asset Done | T1: Task Tổng | U1: Task Xong | V1: Còn lại | W1: % Done | X1: WO/Nội dung
A2: 46209.973 | B2: Nhân viên | C2: Aung Lwin Phyo | D2: MYT_TNI_TEAM01_Dawei | E2: Nhân viên | F2: 0 | G2: 0 | H2: 0 | I2: 0 | J2: 0 | K2: 0/0/0 | M2: 0 | N2: 0 | O2: 0 | P2: 0 | Q2: 0 | R2: 0 | S2: 0 | T2: 0 | U2: 0 | V2: 0 | X2: *Aung Lwin Phyo-myt_tharhtoo.aung11*: 7-day results: *0* M: 0 /26 - Site: *11* : <>Month 17day :0 /Close 7day: 0 <=> rank: *21* =Close: *0% <0/0/0 > WO remain : **33** + Assign: *30 => Task Close Month: 0: 0/0/0* => Asset : 3/P: 0 CM : 5/P: 0 M&E : 11/P: 0 *Detail* : DG Abnormal: TNI0046 - 798, TNI0073 - 1614 : Temperature High: TNI0066 - 3843, TNI0264 - 4539 : DG Run >16H, DG manual TNI0272 06/06/2637, TNI0231 06/06/2637 : Smoke: TNI0073 - 7418, TNI0046 - 747 : Open Door: TNI0265: +Battery Door: 22/05/2026 16:02 - 356, TNI0073: +Battery Door: 01/08/2025 10:01 - 7418, TNI0264: +Battery Door: 03/02/2025 11:20 - 11713 = Run MDG: TNI0035 *=* Site need refuel: TNI0272_1: R- 0 Refuel: *440*L, TNI0073_1: R- 103 Refuel: *440*L, TNI0231_1: R- 221 Refuel: *440*L
A3: 46209.973 | B3: Nhân viên | C3: Bhone Htet Aung | D3: MYT_TNI_TEAM01_Dawei | E3: Nhân viên | F3: 0 | G3: 0 | H3: 0 | I3: 0 | J3: 0 | K3: 0/0/0 | M3: 0 | N3: 0 | O3: 0 | P3: 0 | Q3: 0 | R3: 0 | S3: 0 | T3: 0 | U3: 0 | V3: 0 | X3: *Bhone Htet Aung-myt_bhonehtet.aung*: 7-day results: *0* M: 2 /26 - Site: *13* : 'TNI0271+ TNI0245+ TNI0072+ TNI0070+ TNI0068+ TNI0058+ TNI0050+ TNI0056+ TNI0276+ TNI0062+ TNI0273+ TNI0170+ TNI0214 <>Month 17day :19 /Close 7day: 8 <=> rank: *16* =Close: *44% <0/0/0 > WO remain : **24** + Assign: *25 => Task Close Month: 0: 0/0/0* => Asset : 3/P: 1 PM : 9/P: 0 *Detail* Cell Down: TNI0273 - 111 : DG Abnormal: TNI0170 - 94, TNI0245 - 154, TNI0053 - 323, TNI0214 - 421, TNI0050 - 1276 : : DG Run >16H, DG manual TNI0170 06/06/2637 : Smoke: TNI0058 - 12145, TNI0214 - 12284, TNI0067 - 12796, TNI0251 - 2059, TNI0060 - 5481 : Open Door: TNI0251: +Battery Door: 12/03/2026 17:49 - 2059, TNI0070: +Battery Door: 21/02/2026 11:31 - 2521, TNI0053: +Door Alarm: 04/09/2025 15:16 - 6597, TNI0214: +Battery Door: 03/09/2025 12:19 - 6624, TNI0065: +Battery Door: 28/08/2025 14:39 - 6766, TNI0245: +Battery Door: 01/08/2025 10:31 - 7418, TNI0273: Door open alarm: 24/02/2025 08:41 - 11212 = *=*
A4: 46209.973 | B4: Nhân viên | C4: Bone Myat Naing | D4: MYT_TNI_TEAM01_Dawei | E4: Nhân viên | F4: 0 | G4: 0 | H4: 0 | I4: 0 | J4: 0 | K4: 0/0/0 | M4: 0 | N4: 0 | O4: 0 | P4: 0 | Q4: 0 | R4: 0 | S4: 0 | T4: 0 | U4: 0 | V4: 0 | X4: *Bone Myat Naing-myt_bonemyat.naing1*: 7-day results: *0* M: 4 /26 - Site: *15* : 'TNI0069+ TNI0052+ TNI0071+ TNI0061+ TNI0272+ TNI0257+ TNI0038+ TNI0333+ TNI0041+ TNI0095+ TNI0211+ TNI0328+ TNI0305+ TNI0334+ TNI0051 <>Month 17day :5 /Close 7day: 3 <=> rank: *19* =Close: *15% <0/0/0 > WO remain : **28** + Assign: *16 => Task Close Month: 0: 0/0/0* => CM : 7/P: 0 M&E : 7/P: 0 PM : 1/P: 0 *Detail* Cell Down: TNI0052 - 54, TNI0361 - 101 : DG Abnormal: TNI0051 - 778, TNI0328 - 1402, TNI0211 - 26868 : Temperature High: TNI0306 - 1202, TNI0071 - 3 : DG Run >16H, DG manual TNI0061 06/06/2635, TNI0306 05/06/2650, TNI0031 05/06/2618 : Smoke: TNI0041 - 10942, TNI0069 - 12143, TNI0052 - 26667, TNI0038 - 3045, TNI0306 - 548 : Open Door: TNI0051: +Door Alarm: 06/05/2026 15:52 - 741, TNI0031: DG Door: 21/04/2026 15:25 - 1101, TNI0328: +Door Alarm: 01/11/2023 14:54 +Battery Door: 18/03/2026 15:41 - 1917, TNI0334: +Door Alarm: 04/03/2026 15:42 - 2253, TNI0038: +Door Alarm: 30/01/2026 15:46 +Battery Door: 30/01/2026 15:46 - 3045, TNI0361: Door open alarm: 03/01/2026 06:46 - 3702, TNI0305: +Door Alarm: 30/10/2025 11:05 - 5257, TNI0306: +Door Alarm: 04/10/2025 06:25 - 5886, TNI0095: Door open alarm: 23/09/2025 14:19 - 6142 = Run MDG: TNI0335_01, TNI0305, TNI0333, TNI0041, TNI0334 *=* Site need refuel: TNI0013_1: R- 73 Refuel: *440*L, TNI0061_1: R- 283 Refuel: *220*L, TNI0038_1: R- 0 Refuel: *440*L, TNI0211_1: R- 0 Refuel: *440*L, TNI0051_1: R- 13 Refuel: *440*L, TNI0031_1: R- 303 Refuel: *220*L, TNI0361_1: R- 312 Refuel: *440*L, TNI0052_1: R- 313 Refuel: *220*L, TNI0306_1: R- 316 Refuel: *440*L
A5: 46209.973 | B5: Nhân viên | C5: Win Htet Aung | D5: MYT_TNI_TEAM01_Dawei | E5: Nhân viên | F5: 0 | G5: 0 | H5: 0 | I5: 0 | J5: 0 | K5: 0/0/0 | M5: 0 | N5: 0 | O5: 0 | P5: 0 | Q5: 0 | R5: 0 | S5: 0 | T5: 0 | U5: 0 | V5: 0 | X5: *Win Htet Aung-myt_myothant.htoo*: 7-day results: *1* M: 4 /26 - Site: *4* : 'TNI0247+ TNI0197+ TNI0208+ TNI0264_01 <>Month 17day :0 /Close 7day: 0 <=> rank: *21* =Close: *0% <0/0/0 > WO remain : **6** + Assign: *8 => Task Close Month: 0: 0/0/0* => M&E : 1/P: 0 PM : 3/P: 0 *Detail* Cell Down: TNI0115 - 37, TNI0146 - 39 : DG Abnormal: TNI0019 - 300, TNI0216 - 4784 : : : Smoke: TNI0216 - 7249, TNI0089 - 9867 : Open Door: TNI0054: Door open alarm: 19/02/2026 17:27 - 2563, TNI0216: +Door Alarm: 28/10/2025 10:26 - 5306, TNI0089: +Battery Door: 21/04/2025 09:10 - 9867 = *=* Site need refuel: TNI0089_1: R- 276 Refuel: *220*L, TNI0198_1: R- 21 Refuel: *440*L, TNI0019_1: R- 240 Refuel: *220*L
A6: 46209.973 | B6: Nhân viên | C6: Thar Htoo Aung | D6: MYT_TNI_TEAM01_Dawei | E6: Nhân viên | F6: 0 | G6: 0 | H6: 0 | I6: 0 | J6: 0 | K6: 0/0/0 | M6: 0 | N6: 0 | O6: 0 | P6: 0 | Q6: 0 | R6: 0 | S6: 0 | T6: 0 | U6: 0 | V6: 0 | X6: *Thar Htoo Aung-myt_phyoko.ko44*: 7-day results: *0* M: 0 /26 - Site: *3* : 'TNI0312+ TNI0198+ TNI0278 <>Month 17day :18 /Close 7day: 12 <=> rank: *14* =Close: *45% <0/2/0 > WO remain : **22** + Assign: *8 => Task Close Month: 0: 0/0/0* => Manager : 1/P: 0 Asset : 1/P: 0 CM : 1/P: 0 M&E : 4/P: 0 PM : 1/P: 0 *Detail* Cell Down: TNI0309 - 37, TNI0219 - 40, TNI0322 - 76, TNI0288 - 227 : DG Abnormal: TNI0309 - 36, TNI0319 - 369 : Temperature High: TNI0321 - 2975 : DG Run >16H, DG manual TNI0314 06/06/2638 : Smoke: TNI0322 - 2847, TNI0309 - 9504 : Open Door: TNI0197: Door open alarm: 26/02/2026 10:44 - 2402, TNI0210: +Door Alarm: 04/06/2025 10:08 - 8810 = *=* Site need refuel: TNI0309_1: R- 0 Refuel: *440*L, TNI0319_1: R- 0 Refuel: *440*L, TNI0322_1: R- 150 Refuel: *440*L, TNI0210_1: R- 168 Refuel: *440*L, TNI0321_1: R- 214 Refuel: *440*L, TNI0351_1: R- 85 Refuel: *440*L
A7: 46209.973 | B7: Nhân viên | C7: Maung Maung | D7: MYT_TNI_TEAM02_Myeik | E7: Nhân viên | F7: 0 | G7: 0 | H7: 0 | I7: 0 | J7: 0 | K7: 0/0/0 | M7: 0 | N7: 0 | O7: 0 | P7: 0 | Q7: 0 | R7: 0 | S7: 0 | T7: 0 | U7: 0 | V7: 0 | X7: *Maung Maung-myt_naymyo.thu*: 7-day results: *0* M: 0 /26 - Site: 0 <>Month 17day :2 /Close 7day: 0 <=> rank: *6* =Close: *89% <0/0/0 > WO remain : **2** + Assign: *7 => Task Close Month: 0: 0/0/0* => M&E : 5/P: 0 PM : 2/P: 0 *Detail* Cell Down: TNI0261 - 130 : DG Abnormal: TNI0047 - 855 : : : Smoke: TNI0261 - 5084 : Open Door: TNI0261: +Battery Door: 19/05/2026 15:00 - 429, TNI0024: Door open alarm: 21/04/2026 07:18 - 1109, TNI0398: Door open alarm: 09/11/2025 22:13 - 5006, TNI0258: +Door Alarm: 06/09/2025 14:07 +Battery Door: 16/05/2025 07:00 - 6550, TNI0001: +Door Alarm: 17/12/2024 18:31 - 12858 = *=* Site need refuel: TNI0137_1: R- 301 Refuel: *440*L, TNI0001_1: R- 308 Refuel: *440*L
A8: 46209.973 | B8: Nhân viên | C8: Min Paing Oo | D8: MYT_TNI_TEAM02_Myeik | E8: Nhân viên | F8: 0 | G8: 0 | H8: 0 | I8: 0 | J8: 0 | K8: 0/0/0 | M8: 0 | N8: 0 | O8: 0 | P8: 0 | Q8: 0 | R8: 0 | S8: 0 | T8: 0 | U8: 0 | V8: 0 | X8: *Min Paing Oo-myt_winhtet.aung11*: 7-day results: *0* M: 0 /26 - Site: 0 <>Month 17day :0 /Close 7day: 0 <=> rank: *21* =Close: *0% <0/0/0 > WO remain : **1** + Assign: *4 => Task Close Month: 0: 0/0/0* => Asset : 1/P: 0 M&E : 1/P: 0 PM : 2/P: 0 *Detail* Cell Down: TNI0442 - 37, TNI0234 - 61 : DG Abnormal: TNI0122 - 46, TNI0336 - 85, TNI0289 - 98, TNI0039 - 469, TNI0323 - 687, TNI0090 - 919, TNI0199 - 9671 : Temperature High: TNI0007 - 191 : DG Run >16H, DG manual TNI0291 06/06/2635, TNI0234 06/06/2635, TNI0323 06/06/2637, TNI0291 06/06/260 : : Open Door: TNI0290: Door open alarm: 20/04/2025 04:40 - 9896, TNI0165: Door open alarm: 23/06/2023 11:43 - 25897 = Run MDG: TNI0410, TNI0388, TNI0442 *=* Site need refuel: TNI0007_1: R- 0 Refuel: *440*L, TNI0323_1: R- 135 Refuel: *440*L, TNI0291_1: R- 274 Refuel: *440*L, TNI0339_1: R- 333 Refuel: *440*L
A9: 46209.973 | B9: Nhân viên | C9: Zin Min Shein | D9: MYT_TNI_TEAM02_Myeik | E9: Nhân viên | F9: 0 | G9: 0 | H9: 0 | I9: 0 | J9: 0 | K9: 0/0/0 | M9: 0 | N9: 0 | O9: 0 | P9: 0 | Q9: 0 | R9: 0 | S9: 0 | T9: 0 | U9: 0 | V9: 0 | X9: *Zin Min Shein-myt_zinmin.shein*: 7-day results: *0* M: 0 /26 - Site: *11* : 'TNI0021+ TNI0281+ TNI0519+ TNI0379+ TNI0241+ TNI0042+ TNI0268+ TNI0346+ TNI0406+ TNI0262+ TNI0267 <>Month 17day :23 /Close 7day: 19 <=> rank: *9* =Close: *61% <0/1/2 > WO remain : **15** + Assign: *25 => Task Close Month: 0: 0/0/0* => Manager : 1/P: 13 Asset : 2/P: 0 CM : 7/P: 0 M&E : 7/P: 2 PM : 8/P: 2 *Detail* Cell Down: TNI0042 - 36 : : : DG Run >16H, DG manual TNI0379 06/06/2636 : : Open Door: TNI0519: +Door Alarm: 06/06/2026 11:44 - 1, TNI0267: +Door Alarm: 05/12/2023 17:13 - 21931 = *=* Site need refuel: TNI0379_1: R- 167 Refuel: *440*L
A10: 46209.973 | B10: Nhân viên | C10: Ye Lin | D10: MYT_TNI_TEAM02_Myeik | E10: Nhân viên | F10: 0 | G10: 0 | H10: 0 | I10: 0 | J10: 0 | K10: 0/0/0 | M10: 0 | N10: 0 | O10: 0 | P10: 0 | Q10: 0 | R10: 0 | S10: 0 | T10: 0 | U10: 0 | V10: 0 | X10: *Ye Lin-myt_ye.lin22*: 7-day results: *0* M: 0 /26 - Site: *11* : 'TNI0381+ TNI0277+ TNI0263+ TNI0034+ TNI0020+ TNI0384+ TNI0371+ TNI0237+ TNI0365+ TNI0260+ TNI0423 <>Month 17day :0 /Close 7day: 0 <=> rank: *21* =Close: *0% <0/0/0 > WO remain : **3** + Assign: *5 => Task Close Month: 0: 0/0/0* => Manager : 1/P: 0 M&E : 1/P: 0 PM : 2/P: 0 *Detail* : DG Abnormal: TNI0260 - 2872 : Temperature High: TNI0263 - 17631 : : Smoke: TNI0081 - 12386 : Open Door: TNI0381: Door open alarm: 03/06/2026 13:32 - 71, TNI0020: +Door Alarm: 14/05/2025 15:13 DG Door: 30/06/2025 16:49 - 8180 = *=* Site need refuel: TNI0381_1: R- 0 Refuel: *440*L, TNI0384_1: R- 0 Refuel: *440*L, TNI0385_1: R- 60 Refuel: *440*L, TNI0386_1: R- 187 Refuel: *440*L
A11: 46209.973 | B11: Nhân viên | C11: Wanna Oo | D11: MYT_TNI_TEAM02_Myeik | E11: Nhân viên | F11: 0 | G11: 0 | H11: 0 | I11: 0 | J11: 0 | K11: 0/0/0 | M11: 0 | N11: 0 | O11: 0 | P11: 0 | Q11: 0 | R11: 0 | S11: 0 | T11: 0 | U11: 0 | V11: 0 | X11: *Wanna Oo-myt_wanna.oo2*: 7-day results: *0* M: 0 /26 - Site: *12* : 'TNI0240+ TNI0030+ TNI0003+ TNI0516+ TNI0252+ TNI0255+ TNI0200+ TNI0370+ TNI0279+ TNI0048+ TNI0161+ TNI0440 <>Month 17day :16 /Close 7day: 16 <=> rank: *8* =Close: *62% <0/0/0 > WO remain : **10** + Assign: *13 => Task Close Month: 0: 0/0/0* => CM : 1/P: 0 M&E : 3/P: 0 PM : 7/P: 0 *Detail* Cell Down: TNI0252 - 35 : : Temperature High: TNI0003 - 625 : DG Run >16H, DG manual TNI0200 06/06/2637 : : Open Door: TNI0003: +Door Alarm: 01/06/2026 13:19 - 119, TNI0252: +Door Alarm: 18/02/2026 10:24 - 2594 = *=* Site need refuel: TNI0003_1: R- 256 Refuel: *440*L
A12: 46209.973 | B12: Nhân viên | C12: Myint Ko Ko Aung | D12: MYT_TNI_TEAM03_Bokpyin | E12: Nhân viên | F12: 0 | G12: 0 | H12: 0 | I12: 0 | J12: 0 | K12: 0/0/0 | M12: 0 | N12: 0 | O12: 0 | P12: 0 | Q12: 0 | R12: 0 | S12: 0 | T12: 0 | U12: 0 | V12: 0 | X12: *Myint Ko Ko Aung-myt_sithu.htun*: 7-day results: *0* M: 0 /26 - Site: *9* : 'TNI0196+ TNI0340+ TNI0310+ TNI0124+ TNI0311+ TNI0136+ TNI0345+ TNI0009+ TNI0343 <>Month 17day :5 /Close 7day: 0 <=> rank: *18* =Close: *30% <2/0/1 > WO remain : **21** + Assign: *18 => Task Close Month: 1: 0/0/0* => Manager : 0/P: 13 Asset : 1/P: 0 CM : 6/P: 0 M&E : 3/P: 0 PM : 7/P: 0 *Detail* Cell Down: TNI0004 - 35 : : : DG Run >16H, DG manual TNI0004 04/06/2679, TNI0004 04/06/2644 : Smoke: TNI0116 - 2017 : Open Door: TNI0004: DG Door: 18/06/2025 09:26 - 8475 = Run MDG: TNI0505 *=* Site need refuel: TNI0212_1: R- 51 Refuel: *440*L
A13: 46209.973 | B13: Nhân viên | C13: - | D13: MYT_TNI_TEAM04_Kawthoung | E13: Nhân viên | F13: 0 | G13: 0 | H13: 0 | I13: 0 | J13: 0 | K13: 0/0/0 | M13: 0 | N13: 0 | O13: 0 | P13: 0 | Q13: 0 | R13: 0 | S13: 0 | T13: 0 | U13: 0 | V13: 0 | X13: *--myt_naingmyo.htun*: 7-day results: *0* M: 0 - Site: 0 <>Month 17day :1 /Close 7day: 0 <=> rank: *11* =Close: *50% <0/0/0 > WO remain : **2** + Assign: *2 => Task Close Month: 0: 0/0/0* => PM : 2/P: 0 *Detail*
... A20: 46209.973 | B20: Team Leader | C20: Naing Myo Htun | D20: MYT_TNI_TEAM04_Kawthoung | E20: Team Leader | F20: 0 | G20: 0 | H20: 0 | I20: 0 | J20: 0 | K20: 0/0/0 | M20: 0 | N20: 0 | O20: 0 | P20: 0 | Q20: 0 | R20: 0 | S20: 0 | T20: 0 | U20: 0 | V20: 0 | X20: *Team leader 4* :3-Day Result: 3/0/0/0 <=> rank: *1* =Close: *59%* WO remain : *Month 17day :37/Close 7day: 25 <:> 1/ 2 / 9 / 30* + Assign: *55 => Team leader task Close: 0 All Task Close: 0 : 0 : 0 : 0* => Manager : TL:1 /2 P:0 Asset : TL:16 /17 P:0 CM : TL:0 /5 P:0 M&E : TL:0 /9 P:0 PM : TL:0 /16 P:0 Construction Projects : TL:0 /1 P:0 Finance : TL:5 /5 P:0 *Need complete WO and task:* Week 1 =*25%* <> W2 =*50%* <> W3 = *75%*, W4=*100%* @Naing Myo Htun-Leader T4 -2021 *Sent Plan who do which Site: 08/06/26* Also check *daiy result FT* and Update time run *MDG daily SOS* and googel form. <*> *Aung Myint Myat-myt_arkar.phyo11*: 7-day results: *0* M: 0 /26 - Site: 0 <>Month 17day :0 /Close 7day: 0 <=> rank: *21* =Close: *0% <0/0/0 > WO remain : **13** + Assign: *5 => Task Close Month: 0: 0/0/0* => Asset : 0/P: 1 CM : 2/P: 0 M&E : 1/P: 0 PM : 2/P: 0 *Detail* : : : DG Run >16H, DG manual TNI0227 06/06/2638 : : = *=* *<OTHER>* *Aung Myint Myat-myt_khantchaw.nyo*: 7-day results: *0* M: 0 /26 - Site: *7* : 'TNI0012+ TNI0080+ TNI0064+ TNI0032+ TNI0154+ TNI0509+ TNI0350 <>Month 17day :9 /Close 7day: 4 <=> rank: *1* =Close: *100% <1/0/1 > WO remain : **0** + Assign: *5 => Task Close Month: 0: 0/0/0* => M&E : 2/P: 0 PM : 3/P: 0 *Detail* : : : DG Run >16H, DG manual TNI0227 06/06/2638 : : = *=* *<OTHER>* *Aung Myint Myat-myt_kyawnyein.thu*: 7-day results: *0* M: 0 /26 - Site: 0 <>Month 17day :0 /Close 7day: 0 <=> rank: *21* =Close: *0% <0/0/0 > WO remain : **0** + Assign: *0 => Task Close Month: 0: 0/0/0* => *Detail* : : : DG Run >16H, DG manual TNI0227 06/06/2638 : : = *=* *<OTHER>* *--myt_naingmyo.htun*: 7-day results: *0* M: 0 - Site: 0 <>Month 17day :1 /Close 7day: 0 <=> rank: *11* =Close: *50% <0/0/0 > WO remain : **2** + Assign: *2 => Task Close Month: 0: 0/0/0* => PM : 2/P: 0 *Detail* *<OTHER>* *Tin Maung Win-myt_tinmaung.win*: 7-day results: *0* M: 0 /26 - Site: *1* : TNI0233 <>Month 17day :27 /Close 7day: 21 <=> rank: *7* =Close: *71% <0/2/8 > WO remain : **11** + Assign: *22 => Task Close Month: 0: 0/0/0* => Manager : 1/P: 0 Asset : 2/P: 0 CM : 2/P: 0 M&E : 7/P: 0 PM : 9/P: 0 Construction Projects : 1/P: 0 *Detail* : : : : : Open Door: TNI0123: +Door Alarm: 03/06/2026 09:38 - 75, TNI0295: +Door Alarm: 01/06/2026 12:42 - 120, TNI0372: Door open alarm: 22/07/2023 02:17 - 25210 = Run MDG: TNI0434 *=* Site need refuel: TNI0015_2: R- 194 Refuel: *440*L, TNI0120_1: R- 147 Refuel: *440*L, TNI0404_1: R- 328 Refuel: *440*L
A21: 46209.973 | B21: Đội | C21: MYT_TNI_TEAM01_Dawei | D21: MYT_TNI_TEAM01_Dawei | E21: Tổng đội | F21: 0 | G21: 0 | H21: 0 | I21: 0 | J21: 0 | K21: 0/0/0 | L21: Tất cả | M21: 0 | N21: 0 | O21: 0 | P21: 0 | Q21: 0 | R21: 0 | S21: 0 | T21: 0 | U21: 0 | V21: 0
A22: 46209.973 | B22: Đội | C22: MYT_TNI_TEAM02_Myeik | D22: MYT_TNI_TEAM02_Myeik | E22: Tổng đội | F22: 0 | G22: 0 | H22: 0 | I22: 0 | J22: 0 | K22: 0/0/0 | L22: Tất cả | M22: 0 | N22: 0 | O22: 0 | P22: 0 | Q22: 0 | R22: 0 | S22: 0 | T22: 0 | U22: 0 | V22: 0
A23: 46209.973 | B23: Đội | C23: MYT_TNI_TEAM03_Bokpyin | D23: MYT_TNI_TEAM03_Bokpyin | E23: Tổng đội | F23: 0 | G23: 0 | H23: 0 | I23: 0 | J23: 0 | K23: 0/0/0 | L23: Tất cả | M23: 0 | N23: 0 | O23: 0 | P23: 0 | Q23: 0 | R23: 0 | S23: 0 | T23: 0 | U23: 0 | V23: 0
A24: 46209.973 | B24: Đội | C24: MYT_TNI_TEAM04_Kawthoung | D24: MYT_TNI_TEAM04_Kawthoung | E24: Tổng đội | F24: 0 | G24: 0 | H24: 0 | I24: 0 | J24: 0 | K24: 0/0/0 | L24: Tất cả | M24: 0 | N24: 0 | O24: 0 | P24: 0 | Q24: 0 | R24: 0 | S24: 0 | T24: 0 | U24: 0 | V24: 0
A25: 46209.973 | B25: Technical Dep | C25: Admin | D25: Technical | E25: Technical Dep | F25: 0 | G25: 0 | H25: 0 | I25: 0 | J25: 0 | M25: 0 | N25: 0 | O25: 0 | P25: 0 | Q25: 0 | R25: 0 | S25: 0 | T25: 3 | U25: 0 | V25: 3 | W25: 0
A26: 46209.973 | B26: Technical Dep | C26: Finance | D26: Technical | E26: Technical Dep | F26: 0 | G26: 0 | H26: 0 | I26: 0 | J26: 0 | M26: 0 | N26: 0 | O26: 0 | P26: 0 | Q26: 0 | R26: 0 | S26: 0 | T26: 29 | U26: 7 | V26: 22 | W26: 0.24
A27: 46209.973 | B27: Technical Dep | C27: M&E | D27: Technical | E27: Technical Dep | F27: 0 | G27: 0 | H27: 0 | I27: 0 | J27: 0 | M27: 0 | N27: 0 | O27: 0 | P27: 0 | Q27: 0 | R27: 0 | S27: 0 | T27: 132 | U27: 11 | V27: 121 | W27: 0.08
A28: 46209.973 | B28: Technical Dep | C28: PM | D28: Technical | E28: Technical Dep | F28: 0 | G28: 0 | H28: 0 | I28: 0 | J28: 0 | M28: 0 | N28: 0 | O28: 0 | P28: 0 | Q28: 0 | R28: 0 | S28: 0 | T28: 116 | U28: 25 | V28: 91 | W28: 0.22
A29: 46209.973 | B29: Technical Dep | C29: Transmission | D29: Technical | E29: Technical Dep | F29: 0 | G29: 0 | H29: 0 | I29: 0 | J29: 0 | M29: 0 | N29: 0 | O29: 0 | P29: 0 | Q29: 0 | R29: 0 | S29: 0 | T29: 3 | U29: 1 | V29: 2 | W29: 0.33

Sheet _ChartData_
A1: Đội | B1: 7 Ngày | C1: 1 Tháng
A2: MYT_TNI_TEAM01_Dawei | B2: 0 | C2: 0
A3: MYT_TNI_TEAM02_Myeik | B3: 0 | C3: 0
A4: MYT_TNI_TEAM03_Bokpyin | B4: 0 | C4: 0
A5: MYT_TNI_TEAM04_Kawthoung | B5: 0 | C5: 0
A8: Đội | B8: Tổng Asset
A9: Management | B9: 2
A12: Phòng ban | B12: Xong | C12: Còn lại
A13: Admin | B13: 0 | C13: 3
A14: Finance | B14: 7 | C14: 22
A15: M&E | B15: 11 | C15: 121
A16: PM | B16: 25 | C16: 91
A17: Transmission | B17: 1 | C17: 2

Sheet _meta_
A1: {"s1Start":7,"s1End":25}

Sheet File Site WO
B1: TNI319 | C1: Write full name Site TNI0009 | D1: Write full name Site TNI0009 | E1: Write full name Site TNI0009 | F1: Write full name Site TNI0009 | H1: Check Site Up down run MDG
B2: TNI0071 | C2: TNI0061 | D2: TNI0038 | E2: TNI0328 | F2: TNI0211 | H2: TNI0198
A3: ="Alarm need repair: "&'Site down now'!A1 -> Alarm need repair: Exported Time: 02/07/2026 17:19:55 | B3: {=IFERROR(LET( match_idx, MATCH(B2, 'Site down now'!$B:$B, 0), r_v, INDEX('Site down now'!$R:$R, match_idx), t_v, INDEX('Site down now'!$T:$T, match_idx), u_v, INDEX('Site down now'!$U:$U, match_idx), v_v, INDEX('Site down now'!$V:$V, match_idx), y_v, INDEX('Site down now'!$Y:$Y, match_idx), aa_v, INDEX('Site down now'!$AA:$AA, match_idx), TEXTJOIN(", ", TRUE, IF(AND(r_v<>"", r_v<>0, r_v<>"0.0"), 'Site down now'!$R$2 & ": " & ROUND(r_v, 1), ""), IF(AND(t_v<>"", t_v<>0, t_v<>"0.0"), 'Site down now'!$T$2 & ": " & ROUND(t_v, 1), ""), IF(AND(u_v<>"", u_v<>0, u_v<>"0.0"), 'Site down now'!$U$2 & ": " & ROUND(u_v, 1), ""), IF(AND(v_v<>"", v_v<>0, v_v<>"0.0"), 'Site down now'!$V$2 & ": " & ROUND(v_v, 1), ""), IF(AND(y_v<>"", y_v<>0, y_v<>"0.0"), 'Site down now'!$Y$2 & ": " & ROUND(y_v, 1), ""), IF(AND(aa_v<>"", aa_v<>0, aa_v<>"0.0"), 'Site down now'!$AA$2 & ": " & ROUND(aa_v, 1), "") ) ), "")} -> Battery Temperature High: 8.9 | C3: {=IFERROR(LET( match_idx, MATCH(C2, 'Site down now'!$B:$B, 0), r_v, INDEX('Site down now'!$R:$R, match_idx), t_v, INDEX('Site down now'!$T:$T, match_idx), u_v, INDEX('Site down now'!$U:$U, match_idx), v_v, INDEX('Site down now'!$V:$V, match_idx), y_v, INDEX('Site down now'!$Y:$Y, match_idx), aa_v, INDEX('Site down now'!$AA:$AA, match_idx), TEXTJOIN(", ", TRUE, IF(AND(r_v<>"", r_v<>0, r_v<>"0.0"), 'Site down now'!$R$2 & ": " & ROUND(r_v, 1), ""), IF(AND(t_v<>"", t_v<>0, t_v<>"0.0"), 'Site down now'!$T$2 & ": " & ROUND(t_v, 1), ""), IF(AND(u_v<>"", u_v<>0, u_v<>"0.0"), 'Site down now'!$U$2 & ": " & ROUND(u_v, 1), ""), IF(AND(v_v<>"", v_v<>0, v_v<>"0.0"), 'Site down now'!$V$2 & ": " & ROUND(v_v, 1), ""), IF(AND(y_v<>"", y_v<>0, y_v<>"0.0"), 'Site down now'!$Y$2 & ": " & ROUND(y_v, 1), ""), IF(AND(aa_v<>"", aa_v<>0, aa_v<>"0.0"), 'Site down now'!$AA$2 & ": " & ROUND(aa_v, 1), "") ) ), "")} | D3: {=IFERROR(LET( match_idx, MATCH(D2, 'Site down now'!$B:$B, 0), r_v, INDEX('Site down now'!$R:$R, match_idx), t_v, INDEX('Site down now'!$T:$T, match_idx), u_v, INDEX('Site down now'!$U:$U, match_idx), v_v, INDEX('Site down now'!$V:$V, match_idx), y_v, INDEX('Site down now'!$Y:$Y, match_idx), aa_v, INDEX('Site down now'!$AA:$AA, match_idx), TEXTJOIN(", ", TRUE, IF(AND(r_v<>"", r_v<>0, r_v<>"0.0"), 'Site down now'!$R$2 & ": " & ROUND(r_v, 1), ""), IF(AND(t_v<>"", t_v<>0, t_v<>"0.0"), 'Site down now'!$T$2 & ": " & ROUND(t_v, 1), ""), IF(AND(u_v<>"", u_v<>0, u_v<>"0.0"), 'Site down now'!$U$2 & ": " & ROUND(u_v, 1), ""), IF(AND(v_v<>"", v_v<>0, v_v<>"0.0"), 'Site down now'!$V$2 & ": " & ROUND(v_v, 1), ""), IF(AND(y_v<>"", y_v<>0, y_v<>"0.0"), 'Site down now'!$Y$2 & ": " & ROUND(y_v, 1), ""), IF(AND(aa_v<>"", aa_v<>0, aa_v<>"0.0"), 'Site down now'!$AA$2 & ": " & ROUND(aa_v, 1), "") ) ), "")} -> DG Door Alarm: 3673.6, Battery Cabinet Smoke Alarm: 3673.6 | E3: {=IFERROR(LET( match_idx, MATCH(E2, 'Site down now'!$B:$B, 0), r_v, INDEX('Site down now'!$R:$R, match_idx), t_v, INDEX('Site down now'!$T:$T, match_idx), u_v, INDEX('Site down now'!$U:$U, match_idx), v_v, INDEX('Site down now'!$V:$V, match_idx), y_v, INDEX('Site down now'!$Y:$Y, match_idx), aa_v, INDEX('Site down now'!$AA:$AA, match_idx), TEXTJOIN(", ", TRUE, IF(AND(r_v<>"", r_v<>0, r_v<>"0.0"), 'Site down now'!$R$2 & ": " & ROUND(r_v, 1), ""), IF(AND(t_v<>"", t_v<>0, t_v<>"0.0"), 'Site down now'!$T$2 & ": " & ROUND(t_v, 1), ""), IF(AND(u_v<>"", u_v<>0, u_v<>"0.0"), 'Site down now'!$U$2 & ": " & ROUND(u_v, 1), ""), IF(AND(v_v<>"", v_v<>0, v_v<>"0.0"), 'Site down now'!$V$2 & ": " & ROUND(v_v, 1), ""), IF(AND(y_v<>"", y_v<>0, y_v<>"0.0"), 'Site down now'!$Y$2 & ": " & ROUND(y_v, 1), ""), IF(AND(aa_v<>"", aa_v<>0, aa_v<>"0.0"), 'Site down now'!$AA$2 & ": " & ROUND(aa_v, 1), "") ) ), "")} -> DG Door Alarm: 2545.6, Time Abnormal Alarm: 1997.5 | F3: {=IFERROR(LET( match_idx, MATCH(F2, 'Site down now'!$B:$B, 0), r_v, INDEX('Site down now'!$R:$R, match_idx), t_v, INDEX('Site down now'!$T:$T, match_idx), u_v, INDEX('Site down now'!$U:$U, match_idx), v_v, INDEX('Site down now'!$V:$V, match_idx), y_v, INDEX('Site down now'!$Y:$Y, match_idx), aa_v, INDEX('Site down now'!$AA:$AA, match_idx), TEXTJOIN(", ", TRUE, IF(AND(r_v<>"", r_v<>0, r_v<>"0.0"), 'Site down now'!$R$2 & ": " & ROUND(r_v, 1), ""), IF(AND(t_v<>"", t_v<>0, t_v<>"0.0"), 'Site down now'!$T$2 & ": " & ROUND(t_v, 1), ""), IF(AND(u_v<>"", u_v<>0, u_v<>"0.0"), 'Site down now'!$U$2 & ": " & ROUND(u_v, 1), ""), IF(AND(v_v<>"", v_v<>0, v_v<>"0.0"), 'Site down now'!$V$2 & ": " & ROUND(v_v, 1), ""), IF(AND(y_v<>"", y_v<>0, y_v<>"0.0"), 'Site down now'!$Y$2 & ": " & ROUND(y_v, 1), ""), IF(AND(aa_v<>"", aa_v<>0, aa_v<>"0.0"), 'Site down now'!$AA$2 & ": " & ROUND(aa_v, 1), "") ) ), "")} -> Time Abnormal Alarm: 27463.4
A4: Task | B4: =IFERROR(__xludf.DUMMYFUNCTION("if(len(B$2)<7,""Full TNI0009"",iferror(TEXTJOIN("" |=***=| "",TRUE,filter('Input task'!$D:$D&"" : ""&'Input task'!$E:$E&"" : ""&'Input task'!$K:$K&"" + ""&'Input task'!$H:$H,'Input task'!$J:$J="""",'Input task'!$T:$T=B$2)),""No see""))"),"Fixing Fuel Level Monitoring : TNI0071 Need to fix fuel level cannot monitoring at NMS. : + ") -> Fixing Fuel Level Monitoring : TNI0071 Need to fix fuel level cannot monitoring at NMS. : + | C4: =IFERROR(__xludf.DUMMYFUNCTION("if(len(C$2)<7,""Full TNI0009"",iferror(TEXTJOIN("" |=***=| "",TRUE,filter('Input task'!$D:$D&"" : ""&'Input task'!$E:$E&"" : ""&'Input task'!$K:$K&"" + ""&'Input task'!$H:$H,'Input task'!$J:$J="""",'Input task'!$T:$T=C$2)),""No see""))"),"No see") -> No see | D4: =IFERROR(__xludf.DUMMYFUNCTION("if(len(D$2)<7,""Full TNI0009"",iferror(TEXTJOIN("" |=***=| "",TRUE,filter('Input task'!$D:$D&"" : ""&'Input task'!$E:$E&"" : ""&'Input task'!$K:$K&"" + ""&'Input task'!$H:$H,'Input task'!$J:$J="""",'Input task'!$T:$T=D$2)),""No see""))"),"Request Export material : TNI0038-TNI0051>>24F8 Cable 280M,closure 2pcs, Tension 2pcs : + |=***=| Request Export material : TNI0038-TNI0051>> cable 500M and JB 2pcs : + |=***=| DG Starter Battery : TNI0038 Need to confirm DG starter battery changing f"&"inish sites with M&E : + VCM825430-Aung Thin Myat") -> Request Export material : TNI0038-TNI0051>>24F8 Cable 280M,closure 2pcs, Tension 2pcs : + |=***=| Request Export material : TNI0038-TNI0051>> cable 500M and JB 2pcs : + |=***=| DG Starter Battery : TNI0038 Need to confirm DG starter battery changing finish sites with M&E : + VCM825430-Aung Thin Myat | E4: =IFERROR(__xludf.DUMMYFUNCTION("if(len(E$2)<7,""Full TNI0009"",iferror(TEXTJOIN("" |=***=| "",TRUE,filter('Input task'!$D:$D&"" : ""&'Input task'!$E:$E&"" : ""&'Input task'!$K:$K&"" + ""&'Input task'!$H:$H,'Input task'!$J:$J="""",'Input task'!$T:$T=E$2)),""No see""))"),"Check DG run long time : TNI0328 Need to check DG non stop running : + ") -> Check DG run long time : TNI0328 Need to check DG non stop running : + | F4: =IFERROR(__xludf.DUMMYFUNCTION("if(len(F$2)<7,""Full TNI0009"",iferror(TEXTJOIN("" |=***=| "",TRUE,filter('Input task'!$D:$D&"" : ""&'Input task'!$E:$E&"" : ""&'Input task'!$K:$K&"" + ""&'Input task'!$H:$H,'Input task'!$J:$J="""",'Input task'!$T:$T=F$2)),""No see""))"),"Check DG run long time : TNI0211 Need to check DG non stop running : + ") -> Check DG run long time : TNI0211 Need to check DG non stop running : + | H4: =IFERROR(__xludf.DUMMYFUNCTION("textjoin(CHAR(10),TRUE,Filter('Check New + Clear Site down + Door'!E:OX,'Check New + Clear Site down + Door'!D:D=H2))"),"#REF!") -> #REF!
A5: WO | B5: =IFERROR(__xludf.DUMMYFUNCTION("if(len(B$2)<5,""-"",iferror(TEXTJOIN("" |=***=| "",TRUE,FILTER(('Input WO'!$A:$A&"" + ""&'Input WO'!$B:$B&"" : ""&'Input WO'!$C:$C&"" + ""&'Input WO'!$F:$F),'Input WO'!$E:$E=B$2)),""No see""))"),"WO_WFM-OTHERS_20260622_123602893 + TNI0071_Cleaning Radiator and change engine oil : -41.95 + myt_bhonehtet.aung |=***=| WO_QLCTKT_20260529_123389605 + TNI0071 MYT_Routine_Maintenance_Mytel_Station_VCM : 223.05 + myt_bonemyat.naing1") -> WO_WFM-OTHERS_20260622_123602893 + TNI0071_Cleaning Radiator and change engine oil : -41.95 + myt_bhonehtet.aung |=***=| WO_QLCTKT_20260529_123389605 + TNI0071 MYT_Routine_Maintenance_Mytel_Station_VCM : 223.05 + myt_bonemyat.naing1 | C5: =IFERROR(__xludf.DUMMYFUNCTION("if(len(C$2)<5,""-"",iferror(TEXTJOIN("" |=***=| "",TRUE,FILTER(('Input WO'!$A:$A&"" + ""&'Input WO'!$B:$B&"" : ""&'Input WO'!$C:$C&"" + ""&'Input WO'!$F:$F),'Input WO'!$E:$E=C$2)),""No see""))"),"WO_ICMS_20260623_123611289 + TNI0061 MYT_Routine_Maintenance_Towerco_Station MYT_RTE_MTE_TCO_STN : 882.55 + myt_bhonehtet.aung") -> WO_ICMS_20260623_123611289 + TNI0061 MYT_Routine_Maintenance_Towerco_Station MYT_RTE_MTE_TCO_STN : 882.55 + myt_bhonehtet.aung | D5: =IFERROR(__xludf.DUMMYFUNCTION("if(len(D$2)<5,""-"",iferror(TEXTJOIN("" |=***=| "",TRUE,FILTER(('Input WO'!$A:$A&"" + ""&'Input WO'!$B:$B&"" : ""&'Input WO'!$C:$C&"" + ""&'Input WO'!$F:$F),'Input WO'!$E:$E=D$2)),""No see""))"),"WO_QLCTKT_20260430_123146548 + TNI0038 MYT_Routine_Maintenance_Mytel_Station_VCM : -472.95 + myt_bonemyat.naing1") -> WO_QLCTKT_20260430_123146548 + TNI0038 MYT_Routine_Maintenance_Mytel_Station_VCM : -472.95 + myt_bonemyat.naing1 | E5: =IFERROR(__xludf.DUMMYFUNCTION("if(len(E$2)<5,""-"",iferror(TEXTJOIN("" |=***=| "",TRUE,FILTER(('Input WO'!$A:$A&"" + ""&'Input WO'!$B:$B&"" : ""&'Input WO'!$C:$C&"" + ""&'Input WO'!$F:$F),'Input WO'!$E:$E=E$2)),""No see""))"),"No see") -> No see | F5: =IFERROR(__xludf.DUMMYFUNCTION("if(len(F$2)<5,""-"",iferror(TEXTJOIN("" |=***=| "",TRUE,FILTER(('Input WO'!$A:$A&"" + ""&'Input WO'!$B:$B&"" : ""&'Input WO'!$C:$C&"" + ""&'Input WO'!$F:$F),'Input WO'!$E:$E=F$2)),""No see""))"),"WO_WFM-OTHERS_20260622_123603184 + TNI0211_Cleaning Radiator and change engine oil : -41.95 + myt_bonemyat.naing1") -> WO_WFM-OTHERS_20260622_123603184 + TNI0211_Cleaning Radiator and change engine oil : -41.95 + myt_bonemyat.naing1
A6: 5 | B6: 46087 | C6: 0.73888889 | D6: TEST - Ha Duc Phong | E6: @test | F6: 6859790680 | G6: 50 box cable cat6 | I6: 2 switch 24port | J6: Server TNI0201 sang TNI0065
A7: 6 | B7: 46087 | C7: 0.82777778 | D7: Ha Duc Phong (TEST) | E7: @test | F7: 6859790680 | G7: 50 box cable cat6 | I7: 2 switch 24port | J7: Server TNI0201 sang TNI0065
A8: 7 | B8: 46087 | C8: 0.89305556 | D8: Ha Duc Phong _070756_TNI | E8: @Phongha79 | F8: 6859790680
A9: 8 | B9: 46087 | C9: 0.89583333 | D9: Ha Duc Phong _070756_TNI | E9: @Phongha79 | F9: 6859790680 | G9: TNI0002 1 battery start + 1 ATS charger
A10: 9 | B10: 46087 | C10: 0.89930556 | D10: Ha Duc Phong _070756_TNI | E10: @Phongha79 | F10: 6859790680 | I10: TNI0127 1 RRU
A11: 10 | B11: 46087 | C11: 0.90902778 | D11: Ha Duc Phong _070756_TNI | E11: @Phongha79 | F11: 6859790680
A12: 11 | B12: 46087 | C12: 0.91527778 | D12: Ha Duc Phong _070756_TNI | E12: @Phongha79 | F12: 6859790680 | I12: TNI0127 1 RRU
A13: 12 | B13: 46087 | C13: 0.92847222 | D13: Ha Duc Phong _070756_TNI | E13: @Phongha79 | F13: 6859790680 | I13: TNI0127 1 RRU
A14: 13 | B14: 46087.919 | F14: 123456789

Sheet BOD assign
A1: Assign | B1: Assgin to Backoffice | C1: Group Assign | D1: Detailed content | E1: Date Assign (dd/mm/yyyy) | F1: Target Date complete | G1: Dep update Progress | H1: Dep update Date complete | I1: Dep leader Note | J1: Manager Confirm | K1: Note ( why Deduction) | L1: Auto Count point
A2: =IFERROR(__xludf.DUMMYFUNCTION("IMPORTRANGE(""https://docs.google.com/spreadsheets/d/1grwuZpn4gIku2V66WC59-YccEN2yz1ItIuvgeuzO8W8/edit?gid=1248665610#gid=1248665610"",""Export Assing for BOD + Manager!B9:M"")"),"Admin") -> Admin | B2: =IFERROR(__xludf.DUMMYFUNCTION("""COMPUTED_VALUE"""),"Assign tasks to the team and monitor their progress") -> Assign tasks to the team and monitor their progress | C2: =IFERROR(__xludf.DUMMYFUNCTION("""COMPUTED_VALUE"""),"Team 1 needs to reinstall 2 cameras. Team 1 is required to take photos of the connection points to ensure they are fixed and the cameras' power supply is not disconnected.") -> Team 1 needs to reinstall 2 cameras. Team 1 is required to take photos of the connection points to ensure they are fixed and the cameras' power supply is not disconnected. | D2: =IFERROR(__xludf.DUMMYFUNCTION("""COMPUTED_VALUE"""),"22/06/2026") -> 22/06/2026 | E2: =IFERROR(__xludf.DUMMYFUNCTION("""COMPUTED_VALUE"""),"26/06/2026") -> 26/06/2026 | F2: =IFERROR(__xludf.DUMMYFUNCTION("""COMPUTED_VALUE"""),"#REF!") -> #REF! | G2: =IFERROR(__xludf.DUMMYFUNCTION("""COMPUTED_VALUE"""),"30/06/2026") -> 30/06/2026 | H2: =IFERROR(__xludf.DUMMYFUNCTION("""COMPUTED_VALUE"""),"") | I2: =IFERROR(__xludf.DUMMYFUNCTION("""COMPUTED_VALUE"""),"Confirm completion") -> Confirm completion
A3: =IFERROR(__xludf.DUMMYFUNCTION("""COMPUTED_VALUE"""),"Admin") -> Admin | B3: =IFERROR(__xludf.DUMMYFUNCTION("""COMPUTED_VALUE"""),"Assign tasks to the team and monitor their progress") -> Assign tasks to the team and monitor their progress | C3: =IFERROR(__xludf.DUMMYFUNCTION("""COMPUTED_VALUE"""),"Team 2 needs to reinstall 2 cameras. Team 1 is required to take photos of the connection points to ensure they are fixed and the cameras' power supply is not disconnected.") -> Team 2 needs to reinstall 2 cameras. Team 1 is required to take photos of the connection points to ensure they are fixed and the cameras' power supply is not disconnected. | D3: =IFERROR(__xludf.DUMMYFUNCTION("""COMPUTED_VALUE"""),46195.0) -> 46195 | E3: =IFERROR(__xludf.DUMMYFUNCTION("""COMPUTED_VALUE"""),46199.0) -> 46199
A4: =IFERROR(__xludf.DUMMYFUNCTION("""COMPUTED_VALUE"""),"Admin") -> Admin | B4: =IFERROR(__xludf.DUMMYFUNCTION("""COMPUTED_VALUE"""),"Assign tasks to the team and monitor their progress") -> Assign tasks to the team and monitor their progress | C4: =IFERROR(__xludf.DUMMYFUNCTION("""COMPUTED_VALUE"""),"Team 3 needs to reinstall a camera. Team 3 is required to take photos of the connection point to ensure it is fixed and the camera's power supply is not disconnected.") -> Team 3 needs to reinstall a camera. Team 3 is required to take photos of the connection point to ensure it is fixed and the camera's power supply is not disconnected. | D4: =IFERROR(__xludf.DUMMYFUNCTION("""COMPUTED_VALUE"""),46195.0) -> 46195 | E4: =IFERROR(__xludf.DUMMYFUNCTION("""COMPUTED_VALUE"""),46199.0) -> 46199
A5: =IFERROR(__xludf.DUMMYFUNCTION("""COMPUTED_VALUE"""),"Admin") -> Admin | B5: =IFERROR(__xludf.DUMMYFUNCTION("""COMPUTED_VALUE"""),"Assign tasks to the team and monitor their progress") -> Assign tasks to the team and monitor their progress | C5: =IFERROR(__xludf.DUMMYFUNCTION("""COMPUTED_VALUE"""),"Team 4 needs to reinstall 2 cameras. Team 4 is required to take photos of the connection points to ensure they are fixed and the cameras' power supply is not disconnected.") -> Team 4 needs to reinstall 2 cameras. Team 4 is required to take photos of the connection points to ensure they are fixed and the cameras' power supply is not disconnected. | D5: =IFERROR(__xludf.DUMMYFUNCTION("""COMPUTED_VALUE"""),46195.0) -> 46195 | E5: =IFERROR(__xludf.DUMMYFUNCTION("""COMPUTED_VALUE"""),46203.0) -> 46203
A6: =IFERROR(__xludf.DUMMYFUNCTION("""COMPUTED_VALUE"""),"Admin") -> Admin | B6: =IFERROR(__xludf.DUMMYFUNCTION("""COMPUTED_VALUE"""),"Your task") -> Your task | C6: =IFERROR(__xludf.DUMMYFUNCTION("""COMPUTED_VALUE"""),"Update the daily mileage of cars and motorcycles, and send daily reports.") -> Update the daily mileage of cars and motorcycles, and send daily reports. | D6: =IFERROR(__xludf.DUMMYFUNCTION("""COMPUTED_VALUE"""),46195.0) -> 46195 | E6: =IFERROR(__xludf.DUMMYFUNCTION("""COMPUTED_VALUE"""),46203.0) -> 46203
A7: =IFERROR(__xludf.DUMMYFUNCTION("""COMPUTED_VALUE"""),"Admin") -> Admin | B7: =IFERROR(__xludf.DUMMYFUNCTION("""COMPUTED_VALUE"""),"Your task") -> Your task | C7: =IFERROR(__xludf.DUMMYFUNCTION("""COMPUTED_VALUE"""),"Proactively report any difficulties and progress, send daily reminders via Viber to the team, and contact the team leader directly by phone.") -> Proactively report any difficulties and progress, send daily reminders via Viber to the team, and contact the team leader directly by phone. | D7: =IFERROR(__xludf.DUMMYFUNCTION("""COMPUTED_VALUE"""),46195.0) -> 46195 | E7: =IFERROR(__xludf.DUMMYFUNCTION("""COMPUTED_VALUE"""),46203.0) -> 46203
A8: =IFERROR(__xludf.DUMMYFUNCTION("""COMPUTED_VALUE"""),"Admin") -> Admin | B8: =IFERROR(__xludf.DUMMYFUNCTION("""COMPUTED_VALUE"""),"Your task") -> Your task | C8: =IFERROR(__xludf.DUMMYFUNCTION("""COMPUTED_VALUE"""),"The main team and sub-teams must conduct an inspection of office cleaning on Saturday. Reports must be submitted to the Administration department on Saturday. By Monday, the final filing of office documents must be completed.") -> The main team and sub-teams must conduct an inspection of office cleaning on Saturday. Reports must be submitted to the Administration department on Saturday. By Monday, the final filing of office documents must be completed. | D8: =IFERROR(__xludf.DUMMYFUNCTION("""COMPUTED_VALUE"""),46195.0) -> 46195 | E8: =IFERROR(__xludf.DUMMYFUNCTION("""COMPUTED_VALUE"""),46203.0) -> 46203
A9: =IFERROR(__xludf.DUMMYFUNCTION("""COMPUTED_VALUE"""),"Admin") -> Admin | B9: =IFERROR(__xludf.DUMMYFUNCTION("""COMPUTED_VALUE"""),"Your task") -> Your task | C9: =IFERROR(__xludf.DUMMYFUNCTION("""COMPUTED_VALUE"""),"The admin assigns tasks to the team and checks daily to ensure the team updates and completes the tasks, approving the completed work so that the team receives points.") -> The admin assigns tasks to the team and checks daily to ensure the team updates and completes the tasks, approving the completed work so that the team receives points. | D9: =IFERROR(__xludf.DUMMYFUNCTION("""COMPUTED_VALUE"""),46195.0) -> 46195 | E9: =IFERROR(__xludf.DUMMYFUNCTION("""COMPUTED_VALUE"""),46203.0) -> 46203
A10: =IFERROR(__xludf.DUMMYFUNCTION("""COMPUTED_VALUE"""),"Admin") -> Admin | B10: =IFERROR(__xludf.DUMMYFUNCTION("""COMPUTED_VALUE"""),"Your task") -> Your task | C10: =IFERROR(__xludf.DUMMYFUNCTION("""COMPUTED_VALUE"""),"Search for and rent a car for the office.") -> Search for and rent a car for the office. | D10: =IFERROR(__xludf.DUMMYFUNCTION("""COMPUTED_VALUE"""),46195.0) -> 46195 | E10: =IFERROR(__xludf.DUMMYFUNCTION("""COMPUTED_VALUE"""),46203.0) -> 46203
A11: =IFERROR(__xludf.DUMMYFUNCTION("""COMPUTED_VALUE"""),"Admin") -> Admin | B11: =IFERROR(__xludf.DUMMYFUNCTION("""COMPUTED_VALUE"""),"Your task") -> Your task | C11: =IFERROR(__xludf.DUMMYFUNCTION("""COMPUTED_VALUE"""),"Looking for new office space for TNI branch.") -> Looking for new office space for TNI branch. | D11: =IFERROR(__xludf.DUMMYFUNCTION("""COMPUTED_VALUE"""),46195.0) -> 46195 | E11: =IFERROR(__xludf.DUMMYFUNCTION("""COMPUTED_VALUE"""),46203.0) -> 46203
A12: =IFERROR(__xludf.DUMMYFUNCTION("""COMPUTED_VALUE"""),"Asset") -> Asset | B12: =IFERROR(__xludf.DUMMYFUNCTION("""COMPUTED_VALUE"""),"Your task") -> Your task | C12: =IFERROR(__xludf.DUMMYFUNCTION("""COMPUTED_VALUE"""),"Follow group 1. TNI ASSET ORDER - REVOKE - MOVE... and reply ""Done"" or ""Done: Details as sent but not enough"". You can reply to the sender's message a second or third time until all the required materials are sent. If not enough is sent, reply ""Done:"&" why not send and close the order for this case"".") -> Follow group 1. TNI ASSET ORDER - REVOKE - MOVE... and reply "Done" or "Done: Details as sent but not enough". You can reply to the sender's message a second or third time until all the required materials are sent. If not enough is sent, reply "Done: why not send and close the order for this case". | D12: =IFERROR(__xludf.DUMMYFUNCTION("""COMPUTED_VALUE"""),46195.0) -> 46195 | E12: =IFERROR(__xludf.DUMMYFUNCTION("""COMPUTED_VALUE"""),46203.0) -> 46203
A13: =IFERROR(__xludf.DUMMYFUNCTION("""COMPUTED_VALUE"""),"Asset") -> Asset | B13: =IFERROR(__xludf.DUMMYFUNCTION("""COMPUTED_VALUE"""),"Your task") -> Your task | C13: =IFERROR(__xludf.DUMMYFUNCTION("""COMPUTED_VALUE"""),"Organize the Branch warehouse and the warehouses of Teams 1, 2, 3, and 4 according to 5S guidelines and follow warehouse procedures.") -> Organize the Branch warehouse and the warehouses of Teams 1, 2, 3, and 4 according to 5S guidelines and follow warehouse procedures. | D13: =IFERROR(__xludf.DUMMYFUNCTION("""COMPUTED_VALUE"""),46195.0) -> 46195 | E13: =IFERROR(__xludf.DUMMYFUNCTION("""COMPUTED_VALUE"""),46203.0) -> 46203
A14: =IFERROR(__xludf.DUMMYFUNCTION("""COMPUTED_VALUE"""),"Asset") -> Asset | B14: =IFERROR(__xludf.DUMMYFUNCTION("""COMPUTED_VALUE"""),"Your task") -> Your task | C14: =IFERROR(__xludf.DUMMYFUNCTION("""COMPUTED_VALUE"""),"Inventory control at the VCM warehouse branch.") -> Inventory control at the VCM warehouse branch. | D14: =IFERROR(__xludf.DUMMYFUNCTION("""COMPUTED_VALUE"""),46195.0) -> 46195 | E14: =IFERROR(__xludf.DUMMYFUNCTION("""COMPUTED_VALUE"""),46203.0) -> 46203
A15: =IFERROR(__xludf.DUMMYFUNCTION("""COMPUTED_VALUE"""),"Asset") -> Asset | B15: =IFERROR(__xludf.DUMMYFUNCTION("""COMPUTED_VALUE"""),"Your task") -> Your task | C15: =IFERROR(__xludf.DUMMYFUNCTION("""COMPUTED_VALUE"""),"Support the team in exporting, importing, moving, and revoking M&E assets and materials that need to be shipped to the substation. Information is obtained from Telegram 1. TNI ASSET ORDER - REVOKE - MOVE...") -> Support the team in exporting, importing, moving, and revoking M&E assets and materials that need to be shipped to the substation. Information is obtained from Telegram 1. TNI ASSET ORDER - REVOKE - MOVE... | D15: =IFERROR(__xludf.DUMMYFUNCTION("""COMPUTED_VALUE"""),46195.0) -> 46195 | E15: =IFERROR(__xludf.DUMMYFUNCTION("""COMPUTED_VALUE"""),46203.0) -> 46203
A16: =IFERROR(__xludf.DUMMYFUNCTION("""COMPUTED_VALUE"""),"Asset") -> Asset | B16: =IFERROR(__xludf.DUMMYFUNCTION("""COMPUTED_VALUE"""),"Your task") -> Your task | C16: =IFERROR(__xludf.DUMMYFUNCTION("""COMPUTED_VALUE"""),"Prepare a property loss report and submit it to the CDM.") -> Prepare a property loss report and submit it to the CDM. | D16: =IFERROR(__xludf.DUMMYFUNCTION("""COMPUTED_VALUE"""),46195.0) -> 46195 | E16: =IFERROR(__xludf.DUMMYFUNCTION("""COMPUTED_VALUE"""),46203.0) -> 46203
A17: =IFERROR(__xludf.DUMMYFUNCTION("""COMPUTED_VALUE"""),"Asset") -> Asset | B17: =IFERROR(__xludf.DUMMYFUNCTION("""COMPUTED_VALUE"""),"Your task") -> Your task | C17: =IFERROR(__xludf.DUMMYFUNCTION("""COMPUTED_VALUE"""),"Organize the Branch warehouse and the warehouses of Teams 1, 2, 3, and 4 according to 5S guidelines and follow warehouse procedures.") -> Organize the Branch warehouse and the warehouses of Teams 1, 2, 3, and 4 according to 5S guidelines and follow warehouse procedures. | D17: =IFERROR(__xludf.DUMMYFUNCTION("""COMPUTED_VALUE"""),46195.0) -> 46195 | E17: =IFERROR(__xludf.DUMMYFUNCTION("""COMPUTED_VALUE"""),46203.0) -> 46203
A18: =IFERROR(__xludf.DUMMYFUNCTION("""COMPUTED_VALUE"""),"Asset") -> Asset | B18: =IFERROR(__xludf.DUMMYFUNCTION("""COMPUTED_VALUE"""),"Your task") -> Your task | C18: =IFERROR(__xludf.DUMMYFUNCTION("""COMPUTED_VALUE"""),"Update assets weekly on Google Sheets Assets") -> Update assets weekly on Google Sheets Assets | D18: =IFERROR(__xludf.DUMMYFUNCTION("""COMPUTED_VALUE"""),46195.0) -> 46195 | E18: =IFERROR(__xludf.DUMMYFUNCTION("""COMPUTED_VALUE"""),46203.0) -> 46203
A19: =IFERROR(__xludf.DUMMYFUNCTION("""COMPUTED_VALUE"""),"Asset") -> Asset | B19: =IFERROR(__xludf.DUMMYFUNCTION("""COMPUTED_VALUE"""),"Your task") -> Your task | C19: =IFERROR(__xludf.DUMMYFUNCTION("""COMPUTED_VALUE"""),"Proactively report any difficulties and progress, send daily reminders via Viber to the team, and contact the team leader directly by phone.") -> Proactively report any difficulties and progress, send daily reminders via Viber to the team, and contact the team leader directly by phone. | D19: =IFERROR(__xludf.DUMMYFUNCTION("""COMPUTED_VALUE"""),46195.0) -> 46195 | E19: =IFERROR(__xludf.DUMMYFUNCTION("""COMPUTED_VALUE"""),46203.0) -> 46203
A20: =IFERROR(__xludf.DUMMYFUNCTION("""COMPUTED_VALUE"""),"Asset") -> Asset | B20: =IFERROR(__xludf.DUMMYFUNCTION("""COMPUTED_VALUE"""),"Your task") -> Your task | C20: =IFERROR(__xludf.DUMMYFUNCTION("""COMPUTED_VALUE"""),"Issue all items currently in stock. If an item is missing, make a note of it, locate the missing materials, and record it on the inventory dispatch list.") -> Issue all items currently in stock. If an item is missing, make a note of it, locate the missing materials, and record it on the inventory dispatch list. | D20: =IFERROR(__xludf.DUMMYFUNCTION("""COMPUTED_VALUE"""),46195.0) -> 46195 | E20: =IFERROR(__xludf.DUMMYFUNCTION("""COMPUTED_VALUE"""),46203.0) -> 46203
A21: =IFERROR(__xludf.DUMMYFUNCTION("""COMPUTED_VALUE"""),"CM") -> CM | B21: =IFERROR(__xludf.DUMMYFUNCTION("""COMPUTED_VALUE"""),"Assign tasks to the team and monitor their progress") -> Assign tasks to the team and monitor their progress | C21: =IFERROR(__xludf.DUMMYFUNCTION("""COMPUTED_VALUE"""),"Support the Team by updating progress on the Team's file if completed, and confirming completion on the CM's file when assigning tasks to the Team.") -> Support the Team by updating progress on the Team's file if completed, and confirming completion on the CM's file when assigning tasks to the Team. | D21: =IFERROR(__xludf.DUMMYFUNCTION("""COMPUTED_VALUE"""),46195.0) -> 46195 | E21: =IFERROR(__xludf.DUMMYFUNCTION("""COMPUTED_VALUE"""),46203.0) -> 46203
A22: =IFERROR(__xludf.DUMMYFUNCTION("""COMPUTED_VALUE"""),"CM") -> CM | B22: =IFERROR(__xludf.DUMMYFUNCTION("""COMPUTED_VALUE"""),"Assign tasks to the team and monitor their progress") -> Assign tasks to the team and monitor their progress | C22: =IFERROR(__xludf.DUMMYFUNCTION("""COMPUTED_VALUE"""),"Compile downed cells and manage the team to handle the issue.") -> Compile downed cells and manage the team to handle the issue. | D22: =IFERROR(__xludf.DUMMYFUNCTION("""COMPUTED_VALUE"""),46195.0) -> 46195 | E22: =IFERROR(__xludf.DUMMYFUNCTION("""COMPUTED_VALUE"""),46203.0) -> 46203
A23: =IFERROR(__xludf.DUMMYFUNCTION("""COMPUTED_VALUE"""),"CM") -> CM | B23: =IFERROR(__xludf.DUMMYFUNCTION("""COMPUTED_VALUE"""),"Your task") -> Your task | C23: =IFERROR(__xludf.DUMMYFUNCTION("""COMPUTED_VALUE"""),"Send your daily Cell Down Report at 8:30 AM, 10:50 AM, 1:33 PM, and 5:30 PM.") -> Send your daily Cell Down Report at 8:30 AM, 10:50 AM, 1:33 PM, and 5:30 PM. | D23: =IFERROR(__xludf.DUMMYFUNCTION("""COMPUTED_VALUE"""),46195.0) -> 46195 | E23: =IFERROR(__xludf.DUMMYFUNCTION("""COMPUTED_VALUE"""),46203.0) -> 46203
A24: =IFERROR(__xludf.DUMMYFUNCTION("""COMPUTED_VALUE"""),"CM") -> CM | B24: =IFERROR(__xludf.DUMMYFUNCTION("""COMPUTED_VALUE"""),"Your task") -> Your task | C24: =IFERROR(__xludf.DUMMYFUNCTION("""COMPUTED_VALUE"""),"Monitor updates on the severed cable route on SOS and Push team update ETA and") -> Monitor updates on the severed cable route on SOS and Push team update ETA and | D24: =IFERROR(__xludf.DUMMYFUNCTION("""COMPUTED_VALUE"""),46195.0) -> 46195 | E24: =IFERROR(__xludf.DUMMYFUNCTION("""COMPUTED_VALUE"""),46203.0) -> 46203
A25: =IFERROR(__xludf.DUMMYFUNCTION("""COMPUTED_VALUE"""),"CM") -> CM | B25: =IFERROR(__xludf.DUMMYFUNCTION("""COMPUTED_VALUE"""),"Your task") -> Your task | C25: =IFERROR(__xludf.DUMMYFUNCTION("""COMPUTED_VALUE"""),"Send information about the use of supplies in case of a cable outage to the group via Telegram.") -> Send information about the use of supplies in case of a cable outage to the group via Telegram. | D25: =IFERROR(__xludf.DUMMYFUNCTION("""COMPUTED_VALUE"""),46195.0) -> 46195 | E25: =IFERROR(__xludf.DUMMYFUNCTION("""COMPUTED_VALUE"""),46203.0) -> 46203
A26: =IFERROR(__xludf.DUMMYFUNCTION("""COMPUTED_VALUE"""),"CM") -> CM | B26: =IFERROR(__xludf.DUMMYFUNCTION("""COMPUTED_VALUE"""),"Your task") -> Your task | C26: =IFERROR(__xludf.DUMMYFUNCTION("""COMPUTED_VALUE"""),"Daily Cell*H Reduction Report") -> Daily Cell*H Reduction Report | D26: =IFERROR(__xludf.DUMMYFUNCTION("""COMPUTED_VALUE"""),46195.0) -> 46195 | E26: =IFERROR(__xludf.DUMMYFUNCTION("""COMPUTED_VALUE"""),46203.0) -> 46203
A27: =IFERROR(__xludf.DUMMYFUNCTION("""COMPUTED_VALUE"""),"CM") -> CM | B27: =IFERROR(__xludf.DUMMYFUNCTION("""COMPUTED_VALUE"""),"Your task") -> Your task | C27: =IFERROR(__xludf.DUMMYFUNCTION("""COMPUTED_VALUE"""),"Report downtime stations >2H and cable lines 30 minutes. The team has not responded on the group. Report via Viber to the Board of Directors.") -> Report downtime stations >2H and cable lines 30 minutes. The team has not responded on the group. Report via Viber to the Board of Directors. | D27: =IFERROR(__xludf.DUMMYFUNCTION("""COMPUTED_VALUE"""),46195.0) -> 46195 | E27: =IFERROR(__xludf.DUMMYFUNCTION("""COMPUTED_VALUE"""),46203.0) -> 46203
